Traceback (most recent call last):
  File "/usr/local/lib64/python3.11/site-packages/pandas/core/indexes/base.py", line 3805, in get_loc
    return self._engine.get_loc(casted_key)
           ^^^^^^^^^^^^^^^^^^^^^^^^^^^^^^^^
  File "index.pyx", line 167, in pandas._libs.index.IndexEngine.get_loc
  File "index.pyx", line 196, in pandas._libs.index.IndexEngine.get_loc
  File "pandas/_libs/hashtable_class_helper.pxi", line 7081, in pandas._libs.hashtable.PyObjectHashTable.get_item
  File "pandas/_libs/hashtable_class_helper.pxi", line 7089, in pandas._libs.hashtable.PyObjectHashTable.get_item
KeyError: 'Sample_ID'

The above exception was the direct cause of the following exception:

Traceback (most recent call last):
  File "/home/ay6621/LLMProjCode2/llama-3.py", line 18, in <module>
    df_training['gestational_age'] = df_training['Sample_ID'].map(ano_training['gestational_age'])
                                     ~~~~~~~~~~~^^^^^^^^^^^^^
  File "/usr/local/lib64/python3.11/site-packages/pandas/core/frame.py", line 4102, in __getitem__
    indexer = self.columns.get_loc(key)
              ^^^^^^^^^^^^^^^^^^^^^^^^^
  File "/usr/local/lib64/python3.11/site-packages/pandas/core/indexes/base.py", line 3812, in get_loc
    raise KeyError(key) from err
KeyError: 'Sample_ID'
